Workbook

Sheet Petunjuk
B2: SISKOP — Template Migrasi Saldo Awal v1
B3: Untuk tim onboarding SISKOP. Berkas klien (Excel/PDF/ekspor sistem lama) dikonversi ke template ini, lalu diunggah sebagai draf batch migrasi di tenant klien.
B5: Alur kerja
B6: 1. Klien mengirim dokumen: Neraca yang disahkan RAT, daftar anggota, saldo simpanan per anggota, daftar pembiayaan aktif.
B7: 2. Tim SISKOP mengisi template ini — urutan: Info_Koperasi → Unit → Neraca → Produk → Anggota → Simpanan → Pembiayaan → Penyesuaian.
B8: 3. Buka sheet Rekonsiliasi. Semua status harus OK dan STATUS BATCH = 'SIAP DISETUJUI KLIEN'. Selisih ditanyakan ke Bendahara klien.
B9: 4. Unggah ke tenant klien sebagai DRAF batch migrasi (belum aktif). Sistem menjalankan pemeriksaan yang sama.
B10: 5. Ketua & Bendahara klien meninjau laporan di aplikasi dan menyetujui → saldo awal diposting per tanggal cutover.
B12: Aturan pengisian
B13: • Jangan mengubah nama sheet atau judul kolom baris 1 — sistem membacanya persis. Kolom berawalan '_' dan sheet Rekonsiliasi terisi otomatis.
B14: • Angka murni tanpa 'Rp', titik ribuan, atau spasi. Desimal memakai titik/koma sesuai Excel Anda; maksimal 2 desimal.
B15: • Tanggal dd/mm/yyyy. Semua saldo per tanggalCutover di Info_Koperasi.
... B23: Keterangan warna
B24: contoh | C24: Judul kolom WAJIB
B25: contoh | C25: Judul kolom opsional
B26: contoh | C26: Kolom otomatis (rumus) — jangan diisi
B27: contoh | C27: Sel isian di Info_Koperasi
B29: Kamus kolom (dengan contoh pengisian)
B30: Sheet | C30: Kolom | D30: Wajib | E30: Tipe | F30: Contoh | G30: Keterangan
B31: Unit | C31: kodeUnit | D31: Ya | E31: Teks | F31: KSP01 | G31: Kode singkat unit, dipakai di sheet lain. Contoh: KSP01.
B32: Unit | C32: namaUnit | D32: Ya | E32: Teks | F32: Simpan Pinjam Syariah | G32: Nama unit usaha. Setiap koperasi minimal punya 1 unit.
B33: Unit | C33: jenisUnit | D33: Ya | E33: Teks | F33: KSP | G33: KSP / KONSUMEN / PRODUSEN / JASA / PEMASARAN.
B34: Neraca | C34: kodeAkun | D34: Ya | E34: Teks | F34: 2-1100 | G34: Kode akun COA SISKOP (mis. 1-1000). Unik.
B35: Neraca | C35: namaAkun | D35: Ya | E35: Teks | F35: Simpanan Sukarela Anggota | G35: Nama akun di SISKOP.
B36: Neraca | C36: kategori | D36: Ya | E36: Teks | F36: KEWAJIBAN | G36: ASET / KEWAJIBAN / EKUITAS (neraca pembuka saja).
B37: Neraca | C37: saldoNormal | D37: Ya | E37: Teks | F37: KREDIT | G37: DEBIT atau KREDIT. Akun kontra (mis. akumulasi penyusutan) = kebalikan kategorinya.
B38: Neraca | C38: kelasEkuitas | E38: Teks | G38: Wajib untuk EKUITAS: dipakai untuk Modal Sendiri & Laporan Perubahan Ekuitas.
B39: Neraca | C39: kodeUnit | E39: Teks | G39: Unit pemilik saldo. Kosong = tingkat koperasi (tak teralokasi).
B40: Neraca | C40: saldo | D40: Ya | E40: Rupiah | F40: 3841964000 | G40: Saldo per tanggal cutover, positif searah saldo normal. Angka murni, tanpa 'Rp'.
B41: Neraca | C41: namaDiSumber | D41: Ya | E41: Teks | F41: Simpanan Sukarela | G41: Nama baris persis seperti di Neraca RAT klien — untuk ditelusuri.
B42: Produk | C42: kodeProduk | D42: Ya | E42: Teks | F42: SSK | G42: Kode singkat produk, dipakai di Simpanan/Pembiayaan. Contoh: SW, SSK, MRB.
B43: Produk | C43: namaProduk | D43: Ya | E43: Teks | F43: Tabungan Sukarela | G43: Nama produk di SISKOP.
B44: Produk | C44: jenis | D44: Ya | E44: Teks | F44: SIMPANAN | G44: SIMPANAN atau PEMBIAYAAN.
B45: Produk | C45: jenisSimpanan | E45: Teks | F45: SUKARELA | G45: Untuk SIMPANAN: POKOK / WAJIB / SUKARELA.
B46: Produk | C46: jenisPembiayaan | E46: Teks | G46: Untuk PEMBIAYAAN: SYARIAH / KONVENSIONAL.
B47: Produk | C47: tipeImbalan | D47: Ya | E47: Teks | F47: BAGI_HASIL | G47: BUNGA / BAGI_HASIL / MARGIN / HARIAN.
B48: Produk | C48: tarifPersen | D48: Ya | E48: Persen | F48: 0 | G48: Tarif dalam persen (2.5 = 2,5%). Isi 0 jika tidak ada.
B49: Produk | C49: periode | E49: Teks | F49: YEARLY | G49: Untuk SIMPANAN: DAILY / MONTHLY / YEARLY.
B50: Produk | C50: tenorMaksBulan | E50: Angka | G50: Untuk PEMBIAYAAN: tenor maksimum.
B51: Produk | C51: kodeAkun | D51: Ya | E51: Teks | F51: 2-1100 | G51: Akun Neraca tempat saldo produk ini tercatat. Beberapa produk boleh ke satu akun.
...

Sheet Info_Koperasi
B2: Info Koperasi & Batch Migrasi
B3: Isi sel kuning. Satu file = satu batch migrasi untuk satu koperasi.
B4: Kolom | C4: Isi | D4: Keterangan
B5: namaKoperasi | C5: Koperasi Karyawan Contoh Sejahtera | D5: Nama resmi koperasi sesuai akta
B6: subdomain | C6: kopkar-contoh | D6: Subdomain tenant SISKOP (tanpa .siskop...)
B7: jenisKoperasi | C7: SYARIAH | D7: SYARIAH atau KONVENSIONAL
B8: tanggalCutover | D8: Tanggal tutup buku yang disahkan RAT — semua saldo per tanggal ini
B9: sumberData | C9: EXCEL | D9: Asal data: LEGACY / EXCEL / PDF / CAMPURAN
B10: toleransiSelisih | C10: 1 | D10: Toleransi pembulatan per akun (Rp). Default 1 — ubah hanya dengan persetujuan QA
B11: disiapkanOleh | D11: Nama staf onboarding SISKOP
B12: tanggalDisiapkan | D12: Tanggal file ini disiapkan
B13: versiBatch | C13: v1 | D13: Naikkan setiap kali file dikirim ulang (v1, v2, ...)
B14: dokumenSumber | D14: Daftar berkas asli dari klien (nama file)

Sheet Unit
A1: kodeUnit | B1: namaUnit | C1: jenisUnit

Sheet Neraca
A1: kodeAkun | B1: namaAkun | C1: kategori | D1: saldoNormal | E1: kelasEkuitas | F1: kodeUnit | G1: saldo | H1: namaDiSumber

Sheet Produk
A1: kodeProduk | B1: namaProduk | C1: jenis | D1: jenisSimpanan | E1: jenisPembiayaan | F1: tipeImbalan | G1: tarifPersen | H1: periode | I1: tenorMaksBulan | J1: kodeAkun | K1: kodeUnit | L1: namaDiSumber

Sheet Anggota
A1: noAnggotaLama | B1: namaLengkap | C1: nik | D1: alamat | E1: tempatLahir | F1: tanggalLahir | G1: pekerjaan | H1: noHp | I1: tanggalMasuk | J1: status | K1: pengurus | L1: pengawas | M1: kodeUnit | N1: catatan | O1: _cek_duplikat | P1: _cek_nik
O2: =IF(A2="","",IF(COUNTIF($A$2:$A$2001,A2)>1,"GANDA","OK")) | P2: =IF(A2="","",IF(C2="","KOSONG",IF(AND(LEN(C2)=16,ISNUMBER(--C2)),"OK","TIDAK VALID")))
O3: =IF(A3="","",IF(COUNTIF($A$2:$A$2001,A3)>1,"GANDA","OK")) | P3: =IF(A3="","",IF(C3="","KOSONG",IF(AND(LEN(C3)=16,ISNUMBER(--C3)),"OK","TIDAK VALID")))
O4: =IF(A4="","",IF(COUNTIF($A$2:$A$2001,A4)>1,"GANDA","OK")) | P4: =IF(A4="","",IF(C4="","KOSONG",IF(AND(LEN(C4)=16,ISNUMBER(--C4)),"OK","TIDAK VALID")))
O5: =IF(A5="","",IF(COUNTIF($A$2:$A$2001,A5)>1,"GANDA","OK")) | P5: =IF(A5="","",IF(C5="","KOSONG",IF(AND(LEN(C5)=16,ISNUMBER(--C5)),"OK","TIDAK VALID")))
O6: =IF(A6="","",IF(COUNTIF($A$2:$A$2001,A6)>1,"GANDA","OK")) | P6: =IF(A6="","",IF(C6="","KOSONG",IF(AND(LEN(C6)=16,ISNUMBER(--C6)),"OK","TIDAK VALID")))
O7: =IF(A7="","",IF(COUNTIF($A$2:$A$2001,A7)>1,"GANDA","OK")) | P7: =IF(A7="","",IF(C7="","KOSONG",IF(AND(LEN(C7)=16,ISNUMBER(--C7)),"OK","TIDAK VALID")))
O8: =IF(A8="","",IF(COUNTIF($A$2:$A$2001,A8)>1,"GANDA","OK")) | P8: =IF(A8="","",IF(C8="","KOSONG",IF(AND(LEN(C8)=16,ISNUMBER(--C8)),"OK","TIDAK VALID")))
O9: =IF(A9="","",IF(COUNTIF($A$2:$A$2001,A9)>1,"GANDA","OK")) | P9: =IF(A9="","",IF(C9="","KOSONG",IF(AND(LEN(C9)=16,ISNUMBER(--C9)),"OK","TIDAK VALID")))
O10: =IF(A10="","",IF(COUNTIF($A$2:$A$2001,A10)>1,"GANDA","OK")) | P10: =IF(A10="","",IF(C10="","KOSONG",IF(AND(LEN(C10)=16,ISNUMBER(--C10)),"OK","TIDAK VALID")))
O11: =IF(A11="","",IF(COUNTIF($A$2:$A$2001,A11)>1,"GANDA","OK")) | P11: =IF(A11="","",IF(C11="","KOSONG",IF(AND(LEN(C11)=16,ISNUMBER(--C11)),"OK","TIDAK VALID")))
O12: =IF(A12="","",IF(COUNTIF($A$2:$A$2001,A12)>1,"GANDA","OK")) | P12: =IF(A12="","",IF(C12="","KOSONG",IF(AND(LEN(C12)=16,ISNUMBER(--C12)),"OK","TIDAK VALID")))
O13: =IF(A13="","",IF(COUNTIF($A$2:$A$2001,A13)>1,"GANDA","OK")) | P13: =IF(A13="","",IF(C13="","KOSONG",IF(AND(LEN(C13)=16,ISNUMBER(--C13)),"OK","TIDAK VALID")))
... O2001: =IF(A2001="","",IF(COUNTIF($A$2:$A$2001,A2001)>1,"GANDA","OK")) | P2001: =IF(A2001="","",IF(C2001="","KOSONG",IF(AND(LEN(C2001)=16,ISNUMBER(--C2001)),"OK","TIDAK VALID")))

Sheet Simpanan
A1: noAnggotaLama | B1: namaAnggota | C1: kodeProduk | D1: saldo | E1: catatan | F1: _akun | G1: _cek_anggota
F2: =IF(C2="","",IFERROR(INDEX(Produk!$J$2:$J$100,MATCH(C2,Produk!$A$2:$A$100,0)),"PRODUK?")) | G2: =IF(A2="","",IF(COUNTIF(Anggota!$A$2:$A$2001,A2)=0,"TIDAK ADA","OK"))
F3: =IF(C3="","",IFERROR(INDEX(Produk!$J$2:$J$100,MATCH(C3,Produk!$A$2:$A$100,0)),"PRODUK?")) | G3: =IF(A3="","",IF(COUNTIF(Anggota!$A$2:$A$2001,A3)=0,"TIDAK ADA","OK"))
F4: =IF(C4="","",IFERROR(INDEX(Produk!$J$2:$J$100,MATCH(C4,Produk!$A$2:$A$100,0)),"PRODUK?")) | G4: =IF(A4="","",IF(COUNTIF(Anggota!$A$2:$A$2001,A4)=0,"TIDAK ADA","OK"))
F5: =IF(C5="","",IFERROR(INDEX(Produk!$J$2:$J$100,MATCH(C5,Produk!$A$2:$A$100,0)),"PRODUK?")) | G5: =IF(A5="","",IF(COUNTIF(Anggota!$A$2:$A$2001,A5)=0,"TIDAK ADA","OK"))
F6: =IF(C6="","",IFERROR(INDEX(Produk!$J$2:$J$100,MATCH(C6,Produk!$A$2:$A$100,0)),"PRODUK?")) | G6: =IF(A6="","",IF(COUNTIF(Anggota!$A$2:$A$2001,A6)=0,"TIDAK ADA","OK"))
F7: =IF(C7="","",IFERROR(INDEX(Produk!$J$2:$J$100,MATCH(C7,Produk!$A$2:$A$100,0)),"PRODUK?")) | G7: =IF(A7="","",IF(COUNTIF(Anggota!$A$2:$A$2001,A7)=0,"TIDAK ADA","OK"))
F8: =IF(C8="","",IFERROR(INDEX(Produk!$J$2:$J$100,MATCH(C8,Produk!$A$2:$A$100,0)),"PRODUK?")) | G8: =IF(A8="","",IF(COUNTIF(Anggota!$A$2:$A$2001,A8)=0,"TIDAK ADA","OK"))
F9: =IF(C9="","",IFERROR(INDEX(Produk!$J$2:$J$100,MATCH(C9,Produk!$A$2:$A$100,0)),"PRODUK?")) | G9: =IF(A9="","",IF(COUNTIF(Anggota!$A$2:$A$2001,A9)=0,"TIDAK ADA","OK"))
F10: =IF(C10="","",IFERROR(INDEX(Produk!$J$2:$J$100,MATCH(C10,Produk!$A$2:$A$100,0)),"PRODUK?")) | G10: =IF(A10="","",IF(COUNTIF(Anggota!$A$2:$A$2001,A10)=0,"TIDAK ADA","OK"))
F11: =IF(C11="","",IFERROR(INDEX(Produk!$J$2:$J$100,MATCH(C11,Produk!$A$2:$A$100,0)),"PRODUK?")) | G11: =IF(A11="","",IF(COUNTIF(Anggota!$A$2:$A$2001,A11)=0,"TIDAK ADA","OK"))
F12: =IF(C12="","",IFERROR(INDEX(Produk!$J$2:$J$100,MATCH(C12,Produk!$A$2:$A$100,0)),"PRODUK?")) | G12: =IF(A12="","",IF(COUNTIF(Anggota!$A$2:$A$2001,A12)=0,"TIDAK ADA","OK"))
F13: =IF(C13="","",IFERROR(INDEX(Produk!$J$2:$J$100,MATCH(C13,Produk!$A$2:$A$100,0)),"PRODUK?")) | G13: =IF(A13="","",IF(COUNTIF(Anggota!$A$2:$A$2001,A13)=0,"TIDAK ADA","OK"))
... F2001: =IF(C2001="","",IFERROR(INDEX(Produk!$J$2:$J$100,MATCH(C2001,Produk!$A$2:$A$100,0)),"PRODUK?")) | G2001: =IF(A2001="","",IF(COUNTIF(Anggota!$A$2:$A$2001,A2001)=0,"TIDAK ADA","OK"))

Sheet Pembiayaan
A1: noAnggotaLama | B1: namaAnggota | C1: kodeProduk | D1: noKontrak | E1: tanggalCair | F1: pokokAwal | G1: tenorBulan | H1: sisaPokok | I1: sisaMarginBunga | J1: angsuranPokok | K1: angsuranMarginBunga | L1: sisaAngsuranBulan | M1: hariTunggakan | N1: kolektibilitas | O1: kodeAkunKhusus | P1: catatan | Q1: _akun | R1: _cek_anggota | S1: _cek_angsuran
Q2: =IF(C2="","",IF(O2<>"",O2,IFERROR(INDEX(Produk!$J$2:$J$100,MATCH(C2,Produk!$A$2:$A$100,0)),"PRODUK?"))) | R2: =IF(A2="","",IF(COUNTIF(Anggota!$A$2:$A$2001,A2)=0,"TIDAK ADA","OK")) | S2: =IF(H2="","",IF(OR(J2="",L2=""),"-",IF(ABS(H2-J2*L2)>Info_Koperasi!$C$10,"SELISIH","OK")))
Q3: =IF(C3="","",IF(O3<>"",O3,IFERROR(INDEX(Produk!$J$2:$J$100,MATCH(C3,Produk!$A$2:$A$100,0)),"PRODUK?"))) | R3: =IF(A3="","",IF(COUNTIF(Anggota!$A$2:$A$2001,A3)=0,"TIDAK ADA","OK")) | S3: =IF(H3="","",IF(OR(J3="",L3=""),"-",IF(ABS(H3-J3*L3)>Info_Koperasi!$C$10,"SELISIH","OK")))
Q4: =IF(C4="","",IF(O4<>"",O4,IFERROR(INDEX(Produk!$J$2:$J$100,MATCH(C4,Produk!$A$2:$A$100,0)),"PRODUK?"))) | R4: =IF(A4="","",IF(COUNTIF(Anggota!$A$2:$A$2001,A4)=0,"TIDAK ADA","OK")) | S4: =IF(H4="","",IF(OR(J4="",L4=""),"-",IF(ABS(H4-J4*L4)>Info_Koperasi!$C$10,"SELISIH","OK")))
Q5: =IF(C5="","",IF(O5<>"",O5,IFERROR(INDEX(Produk!$J$2:$J$100,MATCH(C5,Produk!$A$2:$A$100,0)),"PRODUK?"))) | R5: =IF(A5="","",IF(COUNTIF(Anggota!$A$2:$A$2001,A5)=0,"TIDAK ADA","OK")) | S5: =IF(H5="","",IF(OR(J5="",L5=""),"-",IF(ABS(H5-J5*L5)>Info_Koperasi!$C$10,"SELISIH","OK")))
Q6: =IF(C6="","",IF(O6<>"",O6,IFERROR(INDEX(Produk!$J$2:$J$100,MATCH(C6,Produk!$A$2:$A$100,0)),"PRODUK?"))) | R6: =IF(A6="","",IF(COUNTIF(Anggota!$A$2:$A$2001,A6)=0,"TIDAK ADA","OK")) | S6: =IF(H6="","",IF(OR(J6="",L6=""),"-",IF(ABS(H6-J6*L6)>Info_Koperasi!$C$10,"SELISIH","OK")))
Q7: =IF(C7="","",IF(O7<>"",O7,IFERROR(INDEX(Produk!$J$2:$J$100,MATCH(C7,Produk!$A$2:$A$100,0)),"PRODUK?"))) | R7: =IF(A7="","",IF(COUNTIF(Anggota!$A$2:$A$2001,A7)=0,"TIDAK ADA","OK")) | S7: =IF(H7="","",IF(OR(J7="",L7=""),"-",IF(ABS(H7-J7*L7)>Info_Koperasi!$C$10,"SELISIH","OK")))
Q8: =IF(C8="","",IF(O8<>"",O8,IFERROR(INDEX(Produk!$J$2:$J$100,MATCH(C8,Produk!$A$2:$A$100,0)),"PRODUK?"))) | R8: =IF(A8="","",IF(COUNTIF(Anggota!$A$2:$A$2001,A8)=0,"TIDAK ADA","OK")) | S8: =IF(H8="","",IF(OR(J8="",L8=""),"-",IF(ABS(H8-J8*L8)>Info_Koperasi!$C$10,"SELISIH","OK")))
Q9: =IF(C9="","",IF(O9<>"",O9,IFERROR(INDEX(Produk!$J$2:$J$100,MATCH(C9,Produk!$A$2:$A$100,0)),"PRODUK?"))) | R9: =IF(A9="","",IF(COUNTIF(Anggota!$A$2:$A$2001,A9)=0,"TIDAK ADA","OK")) | S9: =IF(H9="","",IF(OR(J9="",L9=""),"-",IF(ABS(H9-J9*L9)>Info_Koperasi!$C$10,"SELISIH","OK")))
Q10: =IF(C10="","",IF(O10<>"",O10,IFERROR(INDEX(Produk!$J$2:$J$100,MATCH(C10,Produk!$A$2:$A$100,0)),"PRODUK?"))) | R10: =IF(A10="","",IF(COUNTIF(Anggota!$A$2:$A$2001,A10)=0,"TIDAK ADA","OK")) | S10: =IF(H10="","",IF(OR(J10="",L10=""),"-",IF(ABS(H10-J10*L10)>Info_Koperasi!$C$10,"SELISIH","OK")))
Q11: =IF(C11="","",IF(O11<>"",O11,IFERROR(INDEX(Produk!$J$2:$J$100,MATCH(C11,Produk!$A$2:$A$100,0)),"PRODUK?"))) | R11: =IF(A11="","",IF(COUNTIF(Anggota!$A$2:$A$2001,A11)=0,"TIDAK ADA","OK")) | S11: =IF(H11="","",IF(OR(J11="",L11=""),"-",IF(ABS(H11-J11*L11)>Info_Koperasi!$C$10,"SELISIH","OK")))
Q12: =IF(C12="","",IF(O12<>"",O12,IFERROR(INDEX(Produk!$J$2:$J$100,MATCH(C12,Produk!$A$2:$A$100,0)),"PRODUK?"))) | R12: =IF(A12="","",IF(COUNTIF(Anggota!$A$2:$A$2001,A12)=0,"TIDAK ADA","OK")) | S12: =IF(H12="","",IF(OR(J12="",L12=""),"-",IF(ABS(H12-J12*L12)>Info_Koperasi!$C$10,"SELISIH","OK")))
Q13: =IF(C13="","",IF(O13<>"",O13,IFERROR(INDEX(Produk!$J$2:$J$100,MATCH(C13,Produk!$A$2:$A$100,0)),"PRODUK?"))) | R13: =IF(A13="","",IF(COUNTIF(Anggota!$A$2:$A$2001,A13)=0,"TIDAK ADA","OK")) | S13: =IF(H13="","",IF(OR(J13="",L13=""),"-",IF(ABS(H13-J13*L13)>Info_Koperasi!$C$10,"SELISIH","OK")))
... Q2001: =IF(C2001="","",IF(O2001<>"",O2001,IFERROR(INDEX(Produk!$J$2:$J$100,MATCH(C2001,Produk!$A$2:$A$100,0)),"PRODUK?"))) | R2001: =IF(A2001="","",IF(COUNTIF(Anggota!$A$2:$A$2001,A2001)=0,"TIDAK ADA","OK")) | S2001: =IF(H2001="","",IF(OR(J2001="",L2001=""),"-",IF(ABS(H2001-J2001*L2001)>Info_Koperasi!$C$10,"SELISIH","OK")))

Sheet Penyesuaian
A1: kodeAkun | B1: jumlah | C1: alasan | D1: buktiSumber | E1: disetujuiOleh | F1: tanggalPersetujuan

Sheet Aset_Tetap
A1: namaAset | B1: jumlahUnit | C1: tanggalPerolehan | D1: hargaPerolehan | E1: akumulasiPenyusutan | F1: _nilaiBuku | G1: kodeAkun | H1: catatan
F2: =IF(D2="","",D2-N(E2))
F3: =IF(D3="","",D3-N(E3))
F4: =IF(D4="","",D4-N(E4))
F5: =IF(D5="","",D5-N(E5))
F6: =IF(D6="","",D6-N(E6))
F7: =IF(D7="","",D7-N(E7))
F8: =IF(D8="","",D8-N(E8))
F9: =IF(D9="","",D9-N(E9))
F10: =IF(D10="","",D10-N(E10))
F11: =IF(D11="","",D11-N(E11))
F12: =IF(D12="","",D12-N(E12))
F13: =IF(D13="","",D13-N(E13))
... F300: =IF(D300="","",D300-N(E300))

Sheet Rekonsiliasi
B2: Rekonsiliasi — wajib hijau semua sebelum dikirim ke klien untuk persetujuan
B3: Semua sel di sheet ini otomatis. Jangan diedit.
C5: Pemeriksaan | D5: Hasil | E5: Status | F5: Syarat
C6: Jumlah anggota | D6: =COUNTA(Anggota!$A$2:$A$2001) -> 0 | E6: ="-" -> - | F6: info
C7: Nomor anggota ganda | D7: =COUNTIF(Anggota!$O$2:$O$2001,"GANDA") -> 0 | E7: =IF(D7=0,"OK","PERBAIKI") -> OK | F7: Harus 0
C8: Anggota tanpa NIK (data belum lengkap) | D8: =COUNTIF(Anggota!$P$2:$P$2001,"KOSONG") -> 0 | E8: ="-" -> - | F8: Boleh > 0 — KYC dilengkapi setelah go-live
C9: NIK tidak valid (bukan 16 digit) | D9: =COUNTIF(Anggota!$P$2:$P$2001,"TIDAK VALID") -> 0 | E9: =IF(D9=0,"OK","PERBAIKI") -> OK | F9: Harus 0 — kosongkan jika tidak yakin
C10: Baris simpanan tanpa anggota | D10: =COUNTIF(Simpanan!$G$2:$G$2001,"TIDAK ADA") -> 0 | E10: =IF(D10=0,"OK","PERBAIKI") -> OK | F10: Harus 0
C11: Baris simpanan dengan produk tak dikenal | D11: =COUNTIF(Simpanan!$F$2:$F$2001,"PRODUK?") -> 0 | E11: =IF(D11=0,"OK","PERBAIKI") -> OK | F11: Harus 0
C12: Saldo simpanan negatif | D12: =COUNTIF(Simpanan!$D$2:$D$2001,"<0") -> 0 | E12: =IF(D12=0,"OK","PERBAIKI") -> OK | F12: Harus 0
C13: Pembiayaan tanpa anggota | D13: =COUNTIF(Pembiayaan!$R$2:$R$2001,"TIDAK ADA") -> 0 | E13: =IF(D13=0,"OK","PERBAIKI") -> OK | F13: Harus 0
C14: Pembiayaan dengan produk tak dikenal | D14: =COUNTIF(Pembiayaan!$Q$2:$Q$2001,"PRODUK?") -> 0 | E14: =IF(D14=0,"OK","PERBAIKI") -> OK | F14: Harus 0
C15: Pembiayaan: sisa pokok ≠ angsuran × sisa bulan | D15: =COUNTIF(Pembiayaan!$S$2:$S$2001,"SELISIH") -> 0 | E15: ="-" -> - | F15: Periksa; boleh > 0 bila ada pelunasan sebagian
C16: Total saldo normal DEBIT (Neraca) | D16: =SUMIFS(Neraca!$G$2:$G$151,Neraca!$D$2:$D$151,"DEBIT") -> 0 | E16: ="-" -> - | F16: info
C17: Total saldo normal KREDIT (Neraca) | D17: =SUMIFS(Neraca!$G$2:$G$151,Neraca!$D$2:$D$151,"KREDIT") -> 0 | E17: ="-" -> - | F17: info
C18: Saldo Awal Migrasi (DEBIT − KREDIT) | D18: =D16-D17 -> 0 | E18: =IF(ABS(D18)<=Info_Koperasi!$C$10,"OK","PERBAIKI") -> OK | F18: Harus 0 (± toleransi)
C19: Akun Neraca yang belum cocok | D19: =COUNTIF($I$26:$I$175,"SELISIH") -> 0 | E19: =IF(D19=0,"OK","PERBAIKI") -> OK | F19: Harus 0
C20: Jumlah akun Neraca terisi | D20: =COUNTA(Neraca!$A$2:$A$151) -> 0 | E20: =IF(D20>0,"OK","PERBAIKI") -> PERBAIKI | F20: Harus > 0
C21: Tanggal cutover terisi | D21: =IF(Info_Koperasi!$C$8="",0,1) -> 0 | E21: =IF(D21>0,"OK","PERBAIKI") -> PERBAIKI | F21: Harus terisi di Info_Koperasi
C22: Penyesuaian belum disetujui pengurus | D22: =SUMPRODUCT((Penyesuaian!$A$2:$A$151<>"")*(Penyesuaian!$E$2:$E$151="")) -> 0 | E22: =IF(D22=0,"OK","PERBAIKI") -> OK | F22: Harus 0 — isi disetujuiOleh setelah konfirmasi klien
B24: Per akun Neraca: saldo Neraca = rincian anggota + penyesuaian | C24: STATUS BATCH | D24: =IF(COUNTIF(E6:E22,"PERBAIKI")=0,"SIAP DISETUJUI KLIEN","BELUM SIAP") -> BELUM SIAP
B25: kodeAkun | C25: namaAkun | D25: Saldo Neraca | E25: Rincian simpanan | F25: Rincian pembiayaan | G25: Penyesuaian | H25: Selisih | I25: Status
B26: =IF(Neraca!A2="","",Neraca!A2) | C26: =IF(B26="","",Neraca!B2) | D26: =IF(B26="","",N(Neraca!G2)) | E26: =IF(B26="","",SUMIFS(Simpanan!$D$2:$D$2001,Simpanan!$F$2:$F$2001,B26)) | F26: =IF(B26="","",SUMIFS(Pembiayaan!$H$2:$H$2001,Pembiayaan!$Q$2:$Q$2001,B26)) | G26: =IF(B26="","",SUMIFS(Penyesuaian!$B$2:$B$151,Penyesuaian!$A$2:$A$151,B26)) | H26: =IF(B26="","",IF(COUNTIF(Produk!$J$2:$J$100,B26)+COUNTIF(Pembiayaan!$O$2:$O$2001,B26)+COUNTIF(Penyesuaian!$A$2:$A$151,B26)=0,"",D26-E26-F26-G26)) | I26: =IF(B26="","",IF(COUNTIF(Produk!$J$2:$J$100,B26)+COUNTIF(Pembiayaan!$O$2:$O$2001,B26)+COUNTIF(Penyesuaian!$A$2:$A$151,B26)=0,"tanpa rincian",IF(ABS(H26)<=Info_Koperasi!$C$10,"COCOK","SELISIH")))
B27: =IF(Neraca!A3="","",Neraca!A3) | C27: =IF(B27="","",Neraca!B3) | D27: =IF(B27="","",N(Neraca!G3)) | E27: =IF(B27="","",SUMIFS(Simpanan!$D$2:$D$2001,Simpanan!$F$2:$F$2001,B27)) | F27: =IF(B27="","",SUMIFS(Pembiayaan!$H$2:$H$2001,Pembiayaan!$Q$2:$Q$2001,B27)) | G27: =IF(B27="","",SUMIFS(Penyesuaian!$B$2:$B$151,Penyesuaian!$A$2:$A$151,B27)) | H27: =IF(B27="","",IF(COUNTIF(Produk!$J$2:$J$100,B27)+COUNTIF(Pembiayaan!$O$2:$O$2001,B27)+COUNTIF(Penyesuaian!$A$2:$A$151,B27)=0,"",D27-E27-F27-G27)) | I27: =IF(B27="","",IF(COUNTIF(Produk!$J$2:$J$100,B27)+COUNTIF(Pembiayaan!$O$2:$O$2001,B27)+COUNTIF(Penyesuaian!$A$2:$A$151,B27)=0,"tanpa rincian",IF(ABS(H27)<=Info_Koperasi!$C$10,"COCOK","SELISIH")))
B28: =IF(Neraca!A4="","",Neraca!A4) | C28: =IF(B28="","",Neraca!B4) | D28: =IF(B28="","",N(Neraca!G4)) | E28: =IF(B28="","",SUMIFS(Simpanan!$D$2:$D$2001,Simpanan!$F$2:$F$2001,B28)) | F28: =IF(B28="","",SUMIFS(Pembiayaan!$H$2:$H$2001,Pembiayaan!$Q$2:$Q$2001,B28)) | G28: =IF(B28="","",SUMIFS(Penyesuaian!$B$2:$B$151,Penyesuaian!$A$2:$A$151,B28)) | H28: =IF(B28="","",IF(COUNTIF(Produk!$J$2:$J$100,B28)+COUNTIF(Pembiayaan!$O$2:$O$2001,B28)+COUNTIF(Penyesuaian!$A$2:$A$151,B28)=0,"",D28-E28-F28-G28)) | I28: =IF(B28="","",IF(COUNTIF(Produk!$J$2:$J$100,B28)+COUNTIF(Pembiayaan!$O$2:$O$2001,B28)+COUNTIF(Penyesuaian!$A$2:$A$151,B28)=0,"tanpa rincian",IF(ABS(H28)<=Info_Koperasi!$C$10,"COCOK","SELISIH")))
B29: =IF(Neraca!A5="","",Neraca!A5) | C29: =IF(B29="","",Neraca!B5) | D29: =IF(B29="","",N(Neraca!G5)) | E29: =IF(B29="","",SUMIFS(Simpanan!$D$2:$D$2001,Simpanan!$F$2:$F$2001,B29)) | F29: =IF(B29="","",SUMIFS(Pembiayaan!$H$2:$H$2001,Pembiayaan!$Q$2:$Q$2001,B29)) | G29: =IF(B29="","",SUMIFS(Penyesuaian!$B$2:$B$151,Penyesuaian!$A$2:$A$151,B29)) | H29: =IF(B29="","",IF(COUNTIF(Produk!$J$2:$J$100,B29)+COUNTIF(Pembiayaan!$O$2:$O$2001,B29)+COUNTIF(Penyesuaian!$A$2:$A$151,B29)=0,"",D29-E29-F29-G29)) | I29: =IF(B29="","",IF(COUNTIF(Produk!$J$2:$J$100,B29)+COUNTIF(Pembiayaan!$O$2:$O$2001,B29)+COUNTIF(Penyesuaian!$A$2:$A$151,B29)=0,"tanpa rincian",IF(ABS(H29)<=Info_Koperasi!$C$10,"COCOK","SELISIH")))
B30: =IF(Neraca!A6="","",Neraca!A6) | C30: =IF(B30="","",Neraca!B6) | D30: =IF(B30="","",N(Neraca!G6)) | E30: =IF(B30="","",SUMIFS(Simpanan!$D$2:$D$2001,Simpanan!$F$2:$F$2001,B30)) | F30: =IF(B30="","",SUMIFS(Pembiayaan!$H$2:$H$2001,Pembiayaan!$Q$2:$Q$2001,B30)) | G30: =IF(B30="","",SUMIFS(Penyesuaian!$B$2:$B$151,Penyesuaian!$A$2:$A$151,B30)) | H30: =IF(B30="","",IF(COUNTIF(Produk!$J$2:$J$100,B30)+COUNTIF(Pembiayaan!$O$2:$O$2001,B30)+COUNTIF(Penyesuaian!$A$2:$A$151,B30)=0,"",D30-E30-F30-G30)) | I30: =IF(B30="","",IF(COUNTIF(Produk!$J$2:$J$100,B30)+COUNTIF(Pembiayaan!$O$2:$O$2001,B30)+COUNTIF(Penyesuaian!$A$2:$A$151,B30)=0,"tanpa rincian",IF(ABS(H30)<=Info_Koperasi!$C$10,"COCOK","SELISIH")))
B31: =IF(Neraca!A7="","",Neraca!A7) | C31: =IF(B31="","",Neraca!B7) | D31: =IF(B31="","",N(Neraca!G7)) | E31: =IF(B31="","",SUMIFS(Simpanan!$D$2:$D$2001,Simpanan!$F$2:$F$2001,B31)) | F31: =IF(B31="","",SUMIFS(Pembiayaan!$H$2:$H$2001,Pembiayaan!$Q$2:$Q$2001,B31)) | G31: =IF(B31="","",SUMIFS(Penyesuaian!$B$2:$B$151,Penyesuaian!$A$2:$A$151,B31)) | H31: =IF(B31="","",IF(COUNTIF(Produk!$J$2:$J$100,B31)+COUNTIF(Pembiayaan!$O$2:$O$2001,B31)+COUNTIF(Penyesuaian!$A$2:$A$151,B31)=0,"",D31-E31-F31-G31)) | I31: =IF(B31="","",IF(COUNTIF(Produk!$J$2:$J$100,B31)+COUNTIF(Pembiayaan!$O$2:$O$2001,B31)+COUNTIF(Penyesuaian!$A$2:$A$151,B31)=0,"tanpa rincian",IF(ABS(H31)<=Info_Koperasi!$C$10,"COCOK","SELISIH")))
B32: =IF(Neraca!A8="","",Neraca!A8) | C32: =IF(B32="","",Neraca!B8) | D32: =IF(B32="","",N(Neraca!G8)) | E32: =IF(B32="","",SUMIFS(Simpanan!$D$2:$D$2001,Simpanan!$F$2:$F$2001,B32)) | F32: =IF(B32="","",SUMIFS(Pembiayaan!$H$2:$H$2001,Pembiayaan!$Q$2:$Q$2001,B32)) | G32: =IF(B32="","",SUMIFS(Penyesuaian!$B$2:$B$151,Penyesuaian!$A$2:$A$151,B32)) | H32: =IF(B32="","",IF(COUNTIF(Produk!$J$2:$J$100,B32)+COUNTIF(Pembiayaan!$O$2:$O$2001,B32)+COUNTIF(Penyesuaian!$A$2:$A$151,B32)=0,"",D32-E32-F32-G32)) | I32: =IF(B32="","",IF(COUNTIF(Produk!$J$2:$J$100,B32)+COUNTIF(Pembiayaan!$O$2:$O$2001,B32)+COUNTIF(Penyesuaian!$A$2:$A$151,B32)=0,"tanpa rincian",IF(ABS(H32)<=Info_Koperasi!$C$10,"COCOK","SELISIH")))
B33: =IF(Neraca!A9="","",Neraca!A9) | C33: =IF(B33="","",Neraca!B9) | D33: =IF(B33="","",N(Neraca!G9)) | E33: =IF(B33="","",SUMIFS(Simpanan!$D$2:$D$2001,Simpanan!$F$2:$F$2001,B33)) | F33: =IF(B33="","",SUMIFS(Pembiayaan!$H$2:$H$2001,Pembiayaan!$Q$2:$Q$2001,B33)) | G33: =IF(B33="","",SUMIFS(Penyesuaian!$B$2:$B$151,Penyesuaian!$A$2:$A$151,B33)) | H33: =IF(B33="","",IF(COUNTIF(Produk!$J$2:$J$100,B33)+COUNTIF(Pembiayaan!$O$2:$O$2001,B33)+COUNTIF(Penyesuaian!$A$2:$A$151,B33)=0,"",D33-E33-F33-G33)) | I33: =IF(B33="","",IF(COUNTIF(Produk!$J$2:$J$100,B33)+COUNTIF(Pembiayaan!$O$2:$O$2001,B33)+COUNTIF(Penyesuaian!$A$2:$A$151,B33)=0,"tanpa rincian",IF(ABS(H33)<=Info_Koperasi!$C$10,"COCOK","SELISIH")))
B34: =IF(Neraca!A10="","",Neraca!A10) | C34: =IF(B34="","",Neraca!B10) | D34: =IF(B34="","",N(Neraca!G10)) | E34: =IF(B34="","",SUMIFS(Simpanan!$D$2:$D$2001,Simpanan!$F$2:$F$2001,B34)) | F34: =IF(B34="","",SUMIFS(Pembiayaan!$H$2:$H$2001,Pembiayaan!$Q$2:$Q$2001,B34)) | G34: =IF(B34="","",SUMIFS(Penyesuaian!$B$2:$B$151,Penyesuaian!$A$2:$A$151,B34)) | H34: =IF(B34="","",IF(COUNTIF(Produk!$J$2:$J$100,B34)+COUNTIF(Pembiayaan!$O$2:$O$2001,B34)+COUNTIF(Penyesuaian!$A$2:$A$151,B34)=0,"",D34-E34-F34-G34)) | I34: =IF(B34="","",IF(COUNTIF(Produk!$J$2:$J$100,B34)+COUNTIF(Pembiayaan!$O$2:$O$2001,B34)+COUNTIF(Penyesuaian!$A$2:$A$151,B34)=0,"tanpa rincian",IF(ABS(H34)<=Info_Koperasi!$C$10,"COCOK","SELISIH")))
B35: =IF(Neraca!A11="","",Neraca!A11) | C35: =IF(B35="","",Neraca!B11) | D35: =IF(B35="","",N(Neraca!G11)) | E35: =IF(B35="","",SUMIFS(Simpanan!$D$2:$D$2001,Simpanan!$F$2:$F$2001,B35)) | F35: =IF(B35="","",SUMIFS(Pembiayaan!$H$2:$H$2001,Pembiayaan!$Q$2:$Q$2001,B35)) | G35: =IF(B35="","",SUMIFS(Penyesuaian!$B$2:$B$151,Penyesuaian!$A$2:$A$151,B35)) | H35: =IF(B35="","",IF(COUNTIF(Produk!$J$2:$J$100,B35)+COUNTIF(Pembiayaan!$O$2:$O$2001,B35)+COUNTIF(Penyesuaian!$A$2:$A$151,B35)=0,"",D35-E35-F35-G35)) | I35: =IF(B35="","",IF(COUNTIF(Produk!$J$2:$J$100,B35)+COUNTIF(Pembiayaan!$O$2:$O$2001,B35)+COUNTIF(Penyesuaian!$A$2:$A$151,B35)=0,"tanpa rincian",IF(ABS(H35)<=Info_Koperasi!$C$10,"COCOK","SELISIH")))
B36: =IF(Neraca!A12="","",Neraca!A12) | C36: =IF(B36="","",Neraca!B12) | D36: =IF(B36="","",N(Neraca!G12)) | E36: =IF(B36="","",SUMIFS(Simpanan!$D$2:$D$2001,Simpanan!$F$2:$F$2001,B36)) | F36: =IF(B36="","",SUMIFS(Pembiayaan!$H$2:$H$2001,Pembiayaan!$Q$2:$Q$2001,B36)) | G36: =IF(B36="","",SUMIFS(Penyesuaian!$B$2:$B$151,Penyesuaian!$A$2:$A$151,B36)) | H36: =IF(B36="","",IF(COUNTIF(Produk!$J$2:$J$100,B36)+COUNTIF(Pembiayaan!$O$2:$O$2001,B36)+COUNTIF(Penyesuaian!$A$2:$A$151,B36)=0,"",D36-E36-F36-G36)) | I36: =IF(B36="","",IF(COUNTIF(Produk!$J$2:$J$100,B36)+COUNTIF(Pembiayaan!$O$2:$O$2001,B36)+COUNTIF(Penyesuaian!$A$2:$A$151,B36)=0,"tanpa rincian",IF(ABS(H36)<=Info_Koperasi!$C$10,"COCOK","SELISIH")))
B37: =IF(Neraca!A13="","",Neraca!A13) | C37: =IF(B37="","",Neraca!B13) | D37: =IF(B37="","",N(Neraca!G13)) | E37: =IF(B37="","",SUMIFS(Simpanan!$D$2:$D$2001,Simpanan!$F$2:$F$2001,B37)) | F37: =IF(B37="","",SUMIFS(Pembiayaan!$H$2:$H$2001,Pembiayaan!$Q$2:$Q$2001,B37)) | G37: =IF(B37="","",SUMIFS(Penyesuaian!$B$2:$B$151,Penyesuaian!$A$2:$A$151,B37)) | H37: =IF(B37="","",IF(COUNTIF(Produk!$J$2:$J$100,B37)+COUNTIF(Pembiayaan!$O$2:$O$2001,B37)+COUNTIF(Penyesuaian!$A$2:$A$151,B37)=0,"",D37-E37-F37-G37)) | I37: =IF(B37="","",IF(COUNTIF(Produk!$J$2:$J$100,B37)+COUNTIF(Pembiayaan!$O$2:$O$2001,B37)+COUNTIF(Penyesuaian!$A$2:$A$151,B37)=0,"tanpa rincian",IF(ABS(H37)<=Info_Koperasi!$C$10,"COCOK","SELISIH")))
... B175: =IF(Neraca!A151="","",Neraca!A151) | C175: =IF(B175="","",Neraca!B151) | D175: =IF(B175="","",N(Neraca!G151)) | E175: =IF(B175="","",SUMIFS(Simpanan!$D$2:$D$2001,Simpanan!$F$2:$F$2001,B175)) | F175: =IF(B175="","",SUMIFS(Pembiayaan!$H$2:$H$2001,Pembiayaan!$Q$2:$Q$2001,B175)) | G175: =IF(B175="","",SUMIFS(Penyesuaian!$B$2:$B$151,Penyesuaian!$A$2:$A$151,B175)) | H175: =IF(B175="","",IF(COUNTIF(Produk!$J$2:$J$100,B175)+COUNTIF(Pembiayaan!$O$2:$O$2001,B175)+COUNTIF(Penyesuaian!$A$2:$A$151,B175)=0,"",D175-E175-F175-G175)) | I175: =IF(B175="","",IF(COUNTIF(Produk!$J$2:$J$100,B175)+COUNTIF(Pembiayaan!$O$2:$O$2001,B175)+COUNTIF(Penyesuaian!$A$2:$A$151,B175)=0,"tanpa rincian",IF(ABS(H175)<=Info_Koperasi!$C$10,"COCOK","SELISIH")))

Sheet Daftar
A1: jenisKoperasi | B1: sumberData | C1: statusAnggota | D1: yaTidak | E1: jenisProduk | F1: jenisSimpanan | G1: jenisPembiayaan | H1: tipeImbalan | I1: periode | J1: kolektibilitas | K1: kategoriAkun | L1: saldoNormal | M1: kelasEkuitas | N1: jenisUnit
A2: SYARIAH | B2: LEGACY | C2: AKTIF | D2: Y | E2: SIMPANAN | F2: POKOK | G2: SYARIAH | H2: BUNGA | I2: DAILY | J2: LANCAR | K2: ASET | L2: DEBIT | M2: SIMPANAN_POKOK | N2: KSP
A3: KONVENSIONAL | B3: EXCEL | C3: KELUAR | D3: N | E3: PEMBIAYAAN | F3: WAJIB | G3: KONVENSIONAL | H3: BAGI_HASIL | I3: MONTHLY | J3: DALAM_PERHATIAN | K3: KEWAJIBAN | L3: KREDIT | M3: SIMPANAN_WAJIB | N3: KONSUMEN
B4: PDF | F4: SUKARELA | H4: MARGIN | I4: YEARLY | J4: KURANG_LANCAR | K4: EKUITAS | M4: MODAL_TETAP | N4: PRODUSEN
B5: CAMPURAN | H5: HARIAN | J5: DIRAGUKAN | M5: CADANGAN_UMUM | N5: JASA
J6: MACET | M6: CADANGAN_RISIKO | N6: PEMASARAN
M7: HIBAH
M8: MODAL_PENYERTAAN
M9: SHU
M10: EKUITAS_LAIN
