Workbook

Sheet Ringkasan
A1: SISKOP — Daftar Rumus Sistem
A2: Disusun dari kode sumber feature/reports-alignment-v2@99a527a, 11 Oktober 2026. Edisi awal: main@0154f9c, 29 September 2026.
A4: Isi workbook
A5: Daftar Rumus | B5: 67 rumus bisnis: definisi, variabel, aturan, jenis aritmetika, file sumber, dasar regulasi.
A6: Simulasi | B6: Kalkulator hidup untuk rumus utama (bagian A–P). Ubah sel kuning berteks biru.
A7: Parameter | B7: Semua konstanta & batas regulasi yang dipakai kode, termasuk batas kelas KSP dan akun tujuan penutupan.
A8: Jurnal Otomatis | B8: 21 pola jurnal Debit/Kredit per jenis transaksi.
A9: Temuan | B9: 11 catatan dari review rumus (float, pembulatan, penamaan, data basi).
A11: Legenda warna
A12: Teks biru + isi kuning | B12: Input — boleh diubah
A13: Teks hitam | B13: Hasil rumus — jangan ditimpa
A14: Teks hijau | B14: Rujukan ke sheet Parameter
A15: Isi kuning muda (Aritmetika) | B15: Rumus dihitung dengan number (float), bukan Decimal
A17: Catatan | B17: Hasil Simulasi mengikuti rumus kode, tetapi Excel menghitung dengan float. Untuk angka resmi, gunakan hasil aplikasi.

Sheet Daftar Rumus
A1: Daftar Rumus SISKOP
A2: Setiap rumus bisnis di kode, per feature/reports-alignment-v2@99a527a (2026-10-11). Kolom 'Aritmetika' menandai apakah dihitung dengan Decimal atau number (float).
A4: No | B4: Modul | C4: Nama Rumus | D4: Rumus | E4: Variabel / Keterangan | F4: Aturan, Batas & Pembulatan | G4: Aritmetika | H4: Sumber Kode | I4: Dasar Regulasi / Keputusan | J4: Simulasi
A5: SIM-01 | B5: Simpanan | C5: Bunga simpanan per periode | D5: Bunga = ROUND(Saldo × Rate ÷ D, 2) D = 360 (DAILY), 12 (MONTHLY), 1 (YEARLY) | E5: Rate = % per tahun dari produk simpanan (SavingConfig.rate); periodUnit hanya menentukan frekuensi kredit | F5: Rate ≤ 9%/tahun. Dibulatkan 2 desimal | G5: number (float) | H5: lib/saving-calc.ts calculateSavingInterest | I5: Permenkop UKM 8/2023 Pasal 26 | J5: D
A6: SIM-02 | B6: Simpanan | C6: Akrual bunga harian (scheduler) | D6: Bunga = ROUND(Saldo × Rate ÷ 36.000, 2) × HariTerlewat HariTerlewat = hari ini − lastInterestAt (run pertama = 1) | E6: Dijalankan harian; saldo dikunci (FOR UPDATE) | F6: Dibulatkan per hari lalu dikali hari; tidak pernah menagih mundur sampai pembukaan rekening | G6: Decimal | H6: savings/daily-interest.ts | J6: D
A7: SIM-03 | B7: Simpanan | C7: Rekening Koran — Saldo Akhir | D7: SaldoAkhir = Saving.balance − Σ mutasi bertanda setelah akhir periode | E7: Mutasi bertanda: PENARIKAN = −jumlah; SETORAN/BUNGA = +jumlah | F7: Periode maks. 366 hari; default awal bulan s/d hari ini | G7: Decimal | H7: savings/service.ts getSavingStatement | J7: E
A8: SIM-04 | B8: Simpanan | C8: Rekening Koran — Saldo Awal & berjalan | D8: SaldoAwal = SaldoAkhir − Σ mutasi bertanda dalam periode Saldo_i = Saldo_(i−1) + Kredit_i − Debit_i | E8: Kredit = setoran + bunga; Debit = penarikan (dari sisi pemilik rekening) | G8: Decimal | H8: savings/service.ts getSavingStatement | J8: E
A9: SIM-05 | B9: Simpanan | C9: Syarat tarik Simpanan Pokok | D9: Boleh tarik Pokok ⇔ tidak ada pinjaman ACTIVE; Saldo ≥ jumlah tarik | F9: Belum ada batas minimum/nol (QA D2) | G9: Decimal | H9: savings/service.ts withdrawFromSaving | I9: AD/ART; UU 25/1992
A10: PIN-01 | B10: Pinjaman | C10: Angsuran anuitas (KONVENSIONAL + BUNGA) | D10: r = Rate ÷ 12 Angsuran = P × r ÷ (1 − (1 + r)^−n) Total = Angsuran × n; Bunga = Total − P Jika r = 0: Angsuran = P ÷ n | E10: P = pokok; n = tenor bulan | F10: Hanya frekuensi MONTHLY. Dibulatkan 2 desimal | G10: number (float) | H10: lib/loan-calc.ts calculateLoan | I10: Rate ≤ 24%/tahun (Pasal 27) | J10: A
A11: PIN-02 | B11: Pinjaman | C11: Flat margin (SYARIAH atau MARGIN) | D11: Margin = P × Rate × n ÷ 12 Total = P + Margin; Angsuran = Total ÷ n | E11: Murabahah / flat | F11: Berlaku untuk semua frekuensi; n untuk DAILY/WEEKLY = PIN-04 | G11: number (float) | H11: lib/loan-calc.ts calculateLoan | J11: B
A12: PIN-03 | B12: Pinjaman | C12: Bunga harian flat (HARIAN) | D12: Bunga = P × Rate ÷ 360 × HariTenor Total = P + Bunga | E12: HariTenor: MONTHLY = hari kalender riil pencairan → jatuh tempo; DAILY = jumlah cicilan; WEEKLY = cicilan × 7; tanpa tanggal = n × 30 | G12: number (float) | H12: lib/loan-calc.ts; loans/service.ts createLoan | J12: C
A13: PIN-04 | B13: Pinjaman | C13: Tenor bulan untuk DAILY/WEEKLY | D13: TenorBulan = MAX(1, ROUNDUP(Hari ÷ 30)) Hari = cicilan (DAILY) atau cicilan × 7 (WEEKLY) | E13: Dipakai untuk angsuran bulanan & flat margin | F13: Pembulatan ke atas menaikkan margin flat (lihat Temuan T4) | G13: integer | H13: loans/service.ts createLoan | J13: C
A14: PIN-05 | B14: Pinjaman | C14: Nominal cicilan jadwal | D14: Rata = Total ÷ JumlahCicilan DAILY/WEEKLY: Cicilan = ROUNDUP(Rata ÷ 500) × 500 MONTHLY: Cicilan = ROUND(Rata, 2) Cicilan terakhir = Total − Σ cicilan sebelumnya | F14: Σ cicilan = Total persis | G14: Decimal | H14: lib/installment-schedule.ts buildSchedule | I14: Keputusan pasar D8 (Rp500) | J14: C
A15: PIN-06 | B15: Pinjaman | C15: Porsi pokok & bunga per cicilan | D15: Pokok_i = ROUND(Cicilan_i × P ÷ Total, 2) Bunga_i = Cicilan_i − Pokok_i Pokok terakhir = P − Σ pokok sebelumnya | G15: Decimal | H15: lib/installment-schedule.ts buildSchedule | J15: C
A16: PIN-07 | B16: Pinjaman | C16: Tanggal jatuh tempo | D16: DAILY: hari operasional ke-i setelah pencairan WEEKLY: pencairan + 7i hari → hari operasional berikutnya MONTHLY: pencairan + i bulan → hari operasional berikutnya | E16: Hari operasional = bukan hari tutup (default Minggu) & bukan hari libur tenant | F16: Tanggal bisnis Asia/Jakarta (UTC+7) | G16: tanggal | H16: lib/installment-schedule.ts; lib/operating-calendar.ts | I16: Keputusan pasar D1
A17: PIN-08 | B17: Pinjaman | C17: Alokasi pembayaran | D17: Untuk tiap cicilan belum lunas, tertua dulu: Dipakai = MIN(sisa bayar, sisa cicilan) Bunga dulu = MIN(Dipakai, sisa bunga); Pokok = Dipakai − Bunga LUNAS jika terbayar ≥ cicilan, else PARTIAL | G17: Decimal | H17: lib/loan-allocation.ts allocatePayment
A18: PIN-09 | B18: Pinjaman | C18: Pemisahan pembayaran (pinjaman tanpa jadwal) | D18: Bunga = ROUND(Bayar × (Total − P) ÷ Total, 2) Pokok = Bayar − Bunga | E18: Hanya pinjaman lama yang belum di-backfill | G18: Decimal | H18: lib/journal.ts splitLoanPayment
A19: PIN-10 | B19: Pinjaman | C19: Sisa pinjaman | D19: Sisa = MAX(0, Sisa − Bayar); status COMPLETED bila 0 | E19: Bayar > Sisa ditolak | F19: Denda diinput manual (tidak dihitung otomatis) | G19: Decimal | H19: loans/service.ts recordLoanPayment | I19: Keputusan pasar D7
A20: PIN-11 | B20: Pinjaman | C20: Override bunga per pinjaman | D20: RateEfektif = rate input bila ≠ rate produk, else rate produk | E20: Wajib isi rateNote bila diubah | F20: ≤ 24%/tahun; tercatat di jejak audit | G20: number (float) | H20: loans/service.ts createLoan | I20: Keputusan pasar D3 | J20: A
A21: PIN-12 | B21: Pinjaman | C21: Hari tunggakan | D21: Dengan jadwal: hari ini − jatuh tempo cicilan belum lunas tertua (0 bila belum jatuh tempo) Tanpa jadwal: maks. hari lewat untuk bulan tanpa pembayaran | F21: Dihitung ulang harian oleh scheduler | G21: integer | H21: lib/kol.ts recalculateKOL | I21: Keputusan pasar D2 | J21: H
A22: PIN-13 | B22: Pinjaman | C22: Kolektibilitas (KOL) | D22: ≤30 Lancar; ≤90 Dalam Perhatian; ≤120 Kurang Lancar; ≤180 Diragukan; >180 Macet | E22: Input = hari tunggakan (PIN-12) | G22: integer | H22: lib/kol.ts getKOLCategory | J22: H
A23: PIN-14 | B23: Pinjaman | C23: BMPP — batas & ruang | D23: Batas = ModalSendiri × % (10% terkait, 15% lainnya) Ruang = MAX(0, Batas − pokok pinjaman ACTIVE) | E23: KSU (>1 unit aktif): Modal Sendiri & pinjaman unit pemberi; tunggal: konsolidasi | G23: Decimal | H23: loans/service.ts computeBmpp | I23: Permenkop UKM 8/2023 Pasal 44–45 | J23: F
A24: PIN-15 | B24: Pinjaman | C24: BMPP — keputusan | D24: Terkait: (aktif + baru) > Batas → DITOLAK Lainnya: ModalSendiri > 0 dan (aktif + baru) > Batas → PERINGATAN, lanjut dengan acknowledgeBmpp | E24: Terkait = pengurus atau pengawas | F24: Modal Sendiri 0 → pihak terkait tidak bisa meminjam | G24: Decimal | H24: loans/service.ts createLoan; lib/regulatory-config.ts | I24: Pasal 44 (blokir), Pasal 45 (peringatan) | J24: F
A25: PIN-16 | B25: Pinjaman | C25: Syarat simpanan pokok | D25: Pinjaman baru hanya bila anggota punya Simpanan Pokok aktif | F25: Pokok bersaldo 0 tetap lolos (Temuan O1 PRD) | G25: boolean | H25: loans/service.ts; savings/service.ts hasPokokSaving
A26: TOK-01 | B26: Toko / POS | C26: Total penjualan & HPP | D26: Total = Σ harga × qty HPP = Σ harga pokok × qty Margin = Total − HPP | E26: Harga dari master produk (bukan dari klien) | F26: Stok harus ≥ qty | G26: Decimal | H26: konsumen/sale.service.ts
A27: TOK-02 | B27: Toko / POS | C27: Nilai restock | D27: Nilai = harga pokok × qty (Dr Persediaan / Cr Kas) | E27: Penyesuaian stok tidak dijurnal | G27: Decimal | H27: konsumen/product.service.ts; lib/journal.ts postStockPurchase
A28: TOK-03 | B28: Toko / POS | C28: Limit Kredit Anggota | D28: Limit = Σ saldo simpanan aktif × 50% Piutang = Σ belanja MEMBER_CREDIT − Σ pelunasan Tersedia = Limit − Piutang Berhak ⇔ punya simpanan aktif dan Limit > 0 | E28: Semua jenis simpanan (Pokok + Wajib + Sukarela) | F28: Dihitung ulang setiap dibaca, tidak disimpan | G28: Decimal | H28: konsumen/credit.service.ts | I28: Keputusan produk | J28: G
A29: PAS-01 | B29: Pasar | C29: Tagihan sewa | D29: Satu tagihan SEWA per ulang tahun periode kontrak (MONTHLY/YEARLY) sejak tanggal mulai Jumlah = rentAmount; jatuh tempo = hari operasional berikutnya | E29: Idempoten per (kontrak, awal periode) | F29: Hanya dibuat pada hari operasional | G29: Decimal | H29: market/charge-generator.ts | I29: Keputusan pasar D1
A30: PAS-02 | B30: Pasar | C30: Tagihan retribusi harian | D30: Satu tagihan RETRIBUSI per hari operasional per tarif DAILY aktif yang cocok (pasar + jenis lapak) Jumlah = levyRate.amount | F30: Retribusi = pendapatan koperasi | G30: Decimal | H30: market/charge-generator.ts | I30: Keputusan pasar D5
A31: PAS-03 | B31: Pasar | C31: Tunggakan angsuran | D31: Σ (pokok + bunga jatuh tempo − pokok + bunga terbayar) cicilan belum lunas dengan jatuh tempo < hari ini | E31: Pinjaman ACTIVE | G31: Decimal | H31: dashboard/service.ts getPasarDashboard
A32: PAS-04 | B32: Pasar | C32: Tunggakan sewa/retribusi | D32: Σ (jumlah − terbayar) tagihan belum lunas dengan jatuh tempo < hari ini | G32: Decimal | H32: dashboard/service.ts getPasarDashboard
A33: PAS-05 | B33: Pasar | C33: Setoran hari ini | D33: Σ expectedTotal batch kolektor dengan tanggal bisnis hari ini | E33: expectedTotal bertambah setiap setoran kolektor | G33: Decimal | H33: collections/service.ts; dashboard/service.ts | J33: M
A34: PAS-06 | B34: Pasar | C34: Selisih setoran kolektor | D34: Selisih = Diterima − Diharapkan Kurang → Dr Piutang Kolektor; Lebih → Cr Selisih Kas | E34: Kolektor tidak boleh memverifikasi batch sendiri | F34: Batch harus SUBMITTED | G34: Decimal | H34: collections/service.ts verifyBatch; lib/journal.ts | J34: M
A35: MOD-01 | B35: Permodalan | C35: Modal Sendiri | D35: MS = Σ saldo akun EKUITAS kelas {Simpanan Pokok, Simpanan Wajib, Modal Tetap, Cadangan Umum, Cadangan Risiko, Hibah} per tanggal + penyesuaian terbaru per cakupan Saldo akun = Kredit − Debit (normal kredit) | E35: Tanpa unit = konsolidasi; dengan unit = unit itu saja | F35: Tidak termasuk Modal Penyertaan, SHU belum dibagi, ekuitas lain | G35: Decimal | H35: reports/capital-service.ts getModalSendiri | I35: Permenkop UKM 8/2023 Pasal 1 angka 23–24 | J35: J
A36: MOD-02 | B36: Permodalan | C36: Rasio Modal Sendiri / Aset | D36: Rasio = MS ÷ Total Aset × 100% | F36: Kosong bila aset 0 | G36: Decimal | H36: dashboard/service.ts getCapitalDashboard | J36: J
A37: MOD-03 | B37: Permodalan | C37: Ambang wajib audit | D37: WAJIB: MS per 31 Des tahun lalu ≥ Rp5 miliar MENDEKATI: MS berjalan ≥ Rp5 miliar Progres = MS ÷ Rp5 miliar | E37: Hanya tenant dengan unit KSP aktif | F37: Notifikasi maks. 1× per jenis per tahun; pengingat, tidak memblokir | G37: Decimal | H37: config/audit-threshold.ts; dashboard/service.ts | I37: Permenkop UKM 2/2024 Pasal 12 | J37: J
A38: MOD-04 | B38: Permodalan | C38: Konsentrasi simpanan | D38: Tampilkan anggota dengan saldo Pokok + Wajib > MS × 20% % = saldo ÷ MS × 100 | F38: Indikator, bukan aturan | G38: Decimal | H38: dashboard/service.ts getCapitalDashboard | J38: J
A39: MOD-05 | B39: Permodalan | C39: Klasifikasi KSP | D39: KSP I/II/III = kelas terendah yang batas anggota, MS dan aset-nya semua terpenuhi; selain itu KSP IV | E39: Batas: lihat sheet Parameter | G39: Decimal | H39: lib/regulatory-config.ts classifyKsp | I39: Permenkop UKM 8/2023 Pasal 49 | J39: K
A40: MOD-06 | B40: Permodalan | C40: Penggunaan BMPP (dashboard) | D40: Penggunaan = pokok aktif ÷ batas BMPP × 100% | E40: Diurutkan dari yang paling dekat batas | G40: Decimal | H40: dashboard/service.ts getCapitalDashboard | J40: F
A41: KUA-01 | B41: Dashboard | C41: Total outstanding | D41: Σ remainingAmount pinjaman ACTIVE (per KOL) | G41: Decimal | H41: dashboard/service.ts getLoanQualityDashboard | J41: I
...

Sheet Simulasi
A1: Simulasi Rumus
A2: Sel kuning berteks biru = input; ubah nilainya dan hasil (hitam) dihitung ulang. Teks hijau = rujukan ke sheet Parameter.
A5: A. Pinjaman Anuitas — KONVENSIONAL + BUNGA, angsuran bulanan (lib/loan-calc.ts)
A6: Pokok pinjaman (P) | B6: 10000000 | C6: Input
A7: Bunga per tahun | B7: 0.18 | C7: Input
A8: Tenor (bulan, n) | B8: 12 | C8: Input
A9: Batas bunga regulasi | B9: =Parameter!$C$5 | C9: Dari Parameter!C5
A10: Lolos batas bunga? | B10: =IF(B7<=B9,"YA","DITOLAK — melebihi batas") | C10: validateRegulatoryRate
A11: Bunga per bulan (r) | B11: =B7/12 | C11: r = bunga tahunan ÷ 12
A12: Angsuran per bulan | B12: =IF(B11=0,ROUND(B6/B8,2),ROUND(B6*B11/(1-(1+B11)^(-B8)),2)) | C12: P × r ÷ (1 − (1 + r)^−n); jika r = 0 → P ÷ n
A13: Total dibayar | B13: =IF(B11=0,B6,ROUND(B6*B11/(1-(1+B11)^(-B8))*B8,2)) | C13: Angsuran (belum dibulatkan) × n
A14: Total bunga | B14: =ROUND(B13-B6,2) | C14: Total − P
A16: B. Pinjaman Flat / Margin — SYARIAH atau rateType MARGIN (lib/loan-calc.ts)
A17: Pokok / harga pokok (P) | B17: 10000000 | C17: Input
A18: Margin per tahun | B18: 0.18 | C18: Input
A19: Tenor (bulan, n) | B19: 12 | C19: Input
A20: Total margin | B20: =ROUND(B17*B18*B19/12,2) | C20: P × margin × n ÷ 12
A21: Total dibayar | B21: =ROUND(B17+B17*B18*B19/12,2) | C21: P + margin
A22: Angsuran per bulan | B22: =ROUND((B17+B17*B18*B19/12)/B19,2) | C22: Total ÷ n
A24: C. Pinjaman Harian (flat) + Jadwal Cicilan Pasar — rateType HARIAN, frekuensi DAILY
A25: Pokok pinjaman (P) | B25: 5000000 | C25: Input
A26: Bunga per tahun | B26: 0.24 | C26: Input
A27: Frekuensi (DAILY / WEEKLY / MONTHLY) | B27: DAILY | C27: Input: DAILY, WEEKLY atau MONTHLY
A28: Jumlah cicilan | B28: 100 | C28: Input. MONTHLY: sama dengan tenor bulan
A29: Hari per tahun (konvensi) | B29: =Parameter!$C$11 | C29: Dari Parameter!C11
A30: Unit pembulatan | B30: =Parameter!$C$12 | C30: Dari Parameter!C12
A31: Hari tenor (termDays) | B31: =IF(B27="DAILY",B28,IF(B27="WEEKLY",B28*7,B28*30)) | C31: DAILY = jumlah cicilan; WEEKLY = × 7. MONTHLY memakai hari kalender riil sampai jatuh tempo (≈ × 30 di sini)
A32: Tenor bulan untuk kalkulasi | B32: =IF(B27="MONTHLY",B28,MAX(1,ROUNDUP(B31/30,0))) | C32: MAX(1, ROUNDUP(hari ÷ 30)) untuk DAILY/WEEKLY — lihat Temuan T4
A33: Total bunga | B33: =ROUND(B25*B26/B29*B31,2) | C33: P × bunga ÷ 360 × hari tenor
A34: Total dibayar | B34: =ROUND(B25+B25*B26/B29*B31,2) | C34: P + bunga
A35: Bagian rata (Total ÷ cicilan) | B35: =B34/B28
A36: Nominal cicilan ke-1 s/d n−1 | B36: =IF(B27="MONTHLY",ROUND(B35,2),ROUNDUP(B35/B30,0)*B30) | C36: DAILY/WEEKLY: dibulatkan KE ATAS ke kelipatan Rp500; MONTHLY: 2 desimal
A37: Nominal cicilan terakhir | B37: =ROUND(B34-(B28-1)*B36,2) | C37: Sisa, sehingga Σ cicilan = Total persis
A38: Porsi pokok cicilan ke-1 | B38: =ROUND(B36*B25/B34,2) | C38: Cicilan × P ÷ Total (cicilan terakhir menyerap sisa)
A39: Porsi bunga cicilan ke-1 | B39: =ROUND(B36-B38,2) | C39: Cicilan − porsi pokok
A41: D. Bunga Simpanan (lib/saving-calc.ts, savings/daily-interest.ts)
A42: Saldo simpanan | B42: 10000000 | C42: Input
A43: Bunga per tahun | B43: 0.06 | C43: Input
A44: Hari sejak lastInterestAt | B44: 3 | C44: Input. Run pertama = 1 hari
A45: Batas bunga simpanan | B45: =Parameter!$C$6 | C45: Dari Parameter!C6
...

Sheet Parameter
A1: Parameter & Konstanta
A2: Nilai tetap di kode. Teks biru = input (ubah untuk simulasi). Sheet Simulasi merujuk sel-sel ini.
A4: Kode | B4: Parameter | C4: Nilai | D4: Satuan | E4: Dasar / Alasan | F4: Sumber Kode
A5: P01 | B5: Batas bunga pinjaman per tahun | C5: 0.24 | D5: % / tahun | E5: Permenkop UKM 8/2023 Pasal 27 | F5: lib/regulatory-config.ts REGULATORY_CAPS
A6: P02 | B6: Batas bunga simpanan per tahun | C6: 0.09 | D6: % / tahun | E6: Permenkop UKM 8/2023 Pasal 26 | F6: lib/regulatory-config.ts REGULATORY_CAPS
A7: P03 | B7: BMPP pihak terkait (pengurus/pengawas) | C7: 0.1 | D7: % Modal Sendiri | E7: Permenkop UKM 8/2023 Pasal 44 — blokir keras | F7: lib/regulatory-config.ts; loans/service.ts computeBmpp
A8: P04 | B8: BMPP anggota lain (tidak terkait) | C8: 0.15 | D8: % Modal Sendiri | E8: Pasal 45 — hanya peringatan, bisa dikonfirmasi | F8: loans/service.ts (acknowledgeBmpp)
A9: P05 | B9: Ambang wajib audit KAP | C9: 5000000000 | D9: Rupiah | E9: Permenkop UKM 2/2024 Pasal 12 (Rp5 miliar); diukur dari Modal Sendiri | F9: lib/regulatory-config.ts MODAL_DISETOR_AUDIT_THRESHOLD_RP
A10: P06 | B10: Limit Kredit Anggota dari total simpanan | C10: 0.5 | D10: rasio | E10: Keputusan produk (Kredit Anggota) | F10: konsumen/credit.service.ts CREDIT_LIMIT_RATIO
A11: P07 | B11: Konvensi hari per tahun | C11: 360 | D11: hari | E11: Konvensi 12 × 30 hari (bunga harian & simpanan) | F11: lib/saving-calc.ts; lib/loan-calc.ts
A12: P08 | B12: Pembulatan cicilan harian/mingguan | C12: 500 | D12: Rupiah | E12: Keputusan pasar D8 — dibulatkan ke atas | F12: lib/installment-schedule.ts ROUNDING_UNIT
A13: P09 | B13: Ambang konsentrasi simpanan pokok+wajib | C13: 0.2 | D13: % Modal Sendiri | E13: Indikator dashboard (bukan aturan) | F13: dashboard/service.ts MEMBER_CAPITAL_CONCENTRATION_PCT
A14: P10 | B14: KOL Lancar: tunggakan maks. | C14: 30 | D14: hari | E14: Keputusan pasar D2 (tidak diubah) | F14: lib/kol.ts getKOLCategory
A15: P11 | B15: KOL Dalam Perhatian: tunggakan maks. | C15: 90 | D15: hari | F15: lib/kol.ts
A16: P12 | B16: KOL Kurang Lancar: tunggakan maks. | C16: 120 | D16: hari | F16: lib/kol.ts
A17: P13 | B17: KOL Diragukan: tunggakan maks. (> = Macet) | C17: 180 | D17: hari | F17: lib/kol.ts
A18: P14 | B18: Retensi jejak audit | C18: 90 | D18: hari | E18: Dihapus harian oleh scheduler | F18: audit-log/service.ts RETENTION_DAYS
A19: P15 | B19: Periode maks. Rekening Koran | C19: 366 | D19: hari | F19: savings/service.ts statement
A20: P16 | B20: Batas pendaftaran mandiri per IP | C20: 5 | D20: per jam | E20: Default, dapat dikonfigurasi | F20: members/public-registration.routes.ts
A21: P17 | B21: Zona waktu tanggal bisnis | C21: 7 | D21: jam (UTC+7) | E21: Asia/Jakarta, tanpa DST | F21: lib/operating-calendar.ts businessDate
A22: P18 | B22: Akun tujuan penutupan default | C22: 3-3100 | D22: kode akun | E22: Akun SHU Tahun Lalu; dapat diganti ke akun EKUITAS rinci aktif lain | F22: modules/journal/year-close.ts resolveTarget
A24: Batas Klasifikasi KSP — Permenkop UKM 8/2023 Pasal 49 (lib/regulatory-config.ts KSP_CLASS_BOUNDS). Melewati salah satu batas = naik kelas.
A25: Kelas | B25: Jumlah anggota maks. | C25: Modal Sendiri maks. | E25: Aset maks.
A26: KSP I | B26: 5000 | C26: 2500000000 | E26: 15000000000
A27: KSP II | B27: 10000 | C27: 15000000000 | E27: 100000000000
A28: KSP III | B28: 30000 | C28: 50000000000 | E28: 500000000000
A29: Di atas KSP III = KSP IV.

Sheet Jurnal Otomatis
A1: Jurnal Otomatis per Transaksi
A2: Akun default dari COA standar (lib/coaTemplate.ts); dapat dipetakan ulang di Konfigurasi → Pemetaan Akun.
A4: Transaksi | B4: Jenis Pemetaan | C4: Debit | D4: Kredit | E4: Jumlah | F4: Catatan
A5: Setoran simpanan | B5: DEPOSIT | C5: Kas | D5: Simpanan (Pokok/Wajib/Sukarela) | E5: Setoran | F5: Per produk simpanan
A6: Penarikan simpanan | B6: WITHDRAWAL | C6: Simpanan | D6: Kas | E6: Penarikan
A7: Bunga simpanan harian | B7: SAVING_INTEREST | C7: Beban Bunga/Bagi Hasil Simpanan | D7: Simpanan | E7: SIM-02 | F7: Tidak dipetakan otomatis — jurnal UNPOSTED sampai dipetakan (Temuan T7)
A8: Pencairan pinjaman | B8: DISBURSEMENT | C8: Piutang Pinjaman Anggota | D8: Kas | E8: Pokok | F8: Default per produk pinjaman
A9: Angsuran — pokok | B9: PAYMENT_PRINCIPAL | C9: Kas | D9: Piutang Pinjaman Anggota | E9: PIN-08
A10: Angsuran — bunga | B10: PAYMENT_INTEREST | C10: Kas | D10: Pendapatan Bunga/Margin Pinjaman | E10: PIN-08
A11: Angsuran — denda | B11: PAYMENT_PENALTY | C11: Kas | D11: Pendapatan Lain-lain | E11: Input manual
A12: Penjualan tunai | B12: SALE_REVENUE | C12: Kas | D12: Penjualan Barang Dagang | E12: TOK-01 Total | F12: Semua-atau-tidak-sama-sekali dengan HPP
A13: Penjualan kredit anggota | B13: SALE_RECEIVABLE | C13: Piutang Anggota (Toko) | D13: Penjualan Barang Dagang | E13: TOK-01 Total
A14: HPP penjualan | B14: SALE_COGS | C14: Harga Pokok Penjualan | D14: Persediaan Barang Dagang | E14: TOK-01 HPP
A15: Pelunasan kredit anggota | B15: MEMBER_CREDIT_REPAYMENT | C15: Kas | D15: Piutang Anggota (Toko) | E15: Pelunasan | F15: Unit: tidak teralokasi
A16: Restock toko | B16: STOCK_PURCHASE | C16: Persediaan Barang Dagang | D16: Kas (atau Utang Usaha) | E16: TOK-02
A17: Transaksi oleh kolektor | B17: COLLECTOR_CASH | C17: Kas di Kolektor (menggantikan Kas) | D17: (sesuai transaksi) | E17: Setoran | F17: Kas diganti Kas di Kolektor sampai diverifikasi
A18: Verifikasi batch kolektor | B18: COLLECTOR_CASH | C18: Kas = diterima; Piutang Kolektor = kekurangan | D18: Kas di Kolektor = diharapkan; Selisih Kas = kelebihan | E18: PAS-06 | F18: Entri majemuk
A19: Tagihan sewa (akrual) | B19: CHARGE_ACCRUAL_SEWA | C19: Piutang Sewa & Retribusi | D19: Pendapatan Sewa Kios | E19: PAS-01
A20: Tagihan retribusi (akrual) | B20: CHARGE_ACCRUAL_RETRIBUSI | C20: Piutang Sewa & Retribusi | D20: Pendapatan Retribusi | E20: PAS-02 | F20: Keputusan D5: pendapatan
A21: Pembayaran tagihan pasar | B21: CHARGE_PAYMENT | C21: Kas / Kas di Kolektor | D21: Piutang Sewa & Retribusi | E21: Pembayaran
A22: Beban Umum | B22: MANUAL_EXPENSE (sumber) | C22: Akun BEBAN pilihan | D22: Kas/Bank (setara kas) | E22: Input | F22: Unit opsional; hapus, tidak bisa edit
A23: Penutupan buku (per unit + tidak teralokasi) | B23: CLOSING (entryType PENUTUP) | C23: Akun PENDAPATAN bersaldo kredit; akun tujuan 3-3100 bila rugi | D23: Akun BEBAN bersaldo debit; akun tujuan 3-3100 bila laba | E23: LAP-15 | F23: Bertanggal 31 Des; saldo tiap akun dinolkan
A24: Pembukaan kembali tahun buku | B24: CLOSING (entryType PENUTUP) | C24: Cermin: kredit entri penutup menjadi debit | D24: Cermin: debit entri penutup menjadi kredit | E24: LAP-16 | F24: reversalOfId menunjuk entri asal; tidak ada yang dihapus
A25: Jurnal manual | B25: MANUAL (UMUM atau PENYESUAIAN) | C25: Akun pilihan (Σ Debit) | D25: Akun pilihan (Σ Kredit) | E25: LAN-06 | F25: Ditolak pada tahun buku tertutup; PENYESUAIAN untuk koreksi akhir periode

Sheet Temuan
A1: Temuan dari Review Rumus
A2: Hal yang terlihat saat menyusun daftar ini. Belum ditriase Engineer/QA.
A4: ID | B4: Temuan | C4: Detail | D4: Lokasi | E4: Rumus
A5: T1 | B5: Bunga simpanan dihitung dengan float | C5: calculateSavingInterest memakai number, melanggar CLAUDE.md aturan 2. Jalur akrual harian scheduler sudah Decimal, jadi dua jalur bisa berbeda di sen terakhir. | D5: lib/saving-calc.ts | E5: SIM-01
A6: T2 | B6: Kalkulasi pinjaman dengan float | C6: calculateLoan menerima principal.toNumber() dan menghitung dalam number sebelum jadwal Decimal dibangun. Total & bunga bisa meleset sen pada nilai besar. | D6: lib/loan-calc.ts; loans/service.ts | E6: PIN-01..03
A7: T3 | B7: Pembagian SHU dengan float | C7: getShuDistribution memakai Number() dan round2 untuk semua pool dan porsi anggota. Σ porsi anggota bisa tidak sama persis dengan pool. | D7: reports/regulatory-service.ts | E7: LAP-03..06
A8: T4 | B8: Margin flat untuk DAILY/WEEKLY memakai bulan dibulatkan ke atas | C8: TenorBulan = ROUNDUP(hari ÷ 30), jadi pinjaman flat 100 hari dihitung 4 bulan (bukan 3,33). Margin naik sekitar 20%. HARIAN tidak terpengaruh (memakai hari). | D8: loans/service.ts createLoan | E8: PIN-02, PIN-04
A9: T5 | B9: Ambang audit memakai Modal Sendiri, nama konstanta Modal Disetor | C9: Pasal 12 menyebut modal; kode memakai Modal Sendiri buku besar. Konstanta tetap bernama MODAL_DISETOR_AUDIT_THRESHOLD_RP; perlu konfirmasi PM bahwa basisnya memang Modal Sendiri. | D9: config/audit-threshold.ts | E9: MOD-03
A10: T6 | B10: Nomor anggota rawan bentrok | C10: Urutan dihitung dari COUNT, bukan sequence DB. Dua pendaftaran bersamaan di bulan yang sama bisa mendapat nomor sama. | D10: lib/id-generator.ts | E10: LAN-01
A11: T7 | B11: Bunga simpanan harian tidak punya pemetaan default | C11: Generate COA membuat pemetaan DEPOSIT/WITHDRAWAL per produk simpanan, tetapi tidak SAVING_INTEREST. Scheduler menambah saldo simpanan, namun jurnalnya tersimpan UNPOSTED_MISSING_MAPPING sampai admin memetakan manual — Neraca tidak mencerminkan beban bunga. | D11: modules/config/service.ts generateStandardCoa; savings/daily-interest.ts | E11: SIM-02
A12: T8 | B12: Pokok bersaldo nol memenuhi syarat pinjaman | C12: hasPokokSaving hanya memeriksa isActive. Terkait QA D1–D3 dan rencana Setoran Awal yang belum diimplementasikan. | D12: savings/service.ts | E12: PIN-16
A13: T9 | B13: PAR bergantung pada job KOL harian | C13: Laporan Kualitas Portofolio membaca Loan.daysOverdue yang terakhir ditulis job harian (recalculateAllKOL). Bila job gagal atau belum jalan, angka PAR basi tanpa tanda apa pun di laporan. | D13: reports/portfolio-service.ts; lib/kol.ts | E13: KUA-05
A14: T10 | B14: Efisiensi penagihan memakai 'terbayar sampai sekarang' | C14: principalPaid + interestPaid bersifat kumulatif, bukan terbayar sampai akhir periode. Efisiensi bulan lampau naik seiring waktu dan tidak bisa direproduksi persis di kemudian hari. | D14: reports/portfolio-service.ts getCollectionEfficiency | E14: KUA-08
A15: T11 | B15: Outstanding pinjaman tanpa jadwal memakai porsi pokok flat | C15: Fallback remainingAmount × pokok ÷ total mengandaikan pembayaran terdistribusi proporsional; untuk pinjaman anuitas lama hanya pendekatan. | D15: reports/portfolio-service.ts outstandingSql | E15: KUA-07
